<?xml version="1.0"?>
<robot name="hobo">
    <link name="base_link">
        <visual>
            <geometry>
                <cylinder length="0.01" radius="0.25"/>
            </geometry>
            <material name="silver">
                <color rgba="0.75 0.75 0.75 1"/>
            </material>
        </visual>
        <collision>
            <geometry>
                <cylinder length="0.01" radius="0.25"/>
            </geometry>
        </collision>
        <inertial>
            <origin xyz="0 0 0" rpy="0 0 0"/>
            <mass value="1.0" />
            <inertia ixx="0.0741666666667" ixy="0.0" ixz="0.0" iyy="0.0585416666667" iyz="0.0" izz="0.0260416666667"/>
        </inertial>
    </link>
    <link name="left_wheel">
        <visual>
            <geometry>
                <cylinder length="0.05" radius="0.05"/>
            </geometry>
            <material name="black"/>
        </visual>
        <collision>
            <geometry>
                <cylinder length="0.05" radius="0.05"/>
            </geometry>
        </collision>
    </link>
    <joint name="left_wheel_to_base" type="continuous">
        <axis xyz="0 0 1"/>
        <parent link="base_link"/>
        <child link="left_wheel"/>
        <origin rpy="0 -1.5708 0" xyz="-0.275 0 0"/>
        <inertial>
            <mass value="1.0"/>
            <inertia ixx="5.1458e-5" iyy="5.1458e-5" izz="5.1458e-5" ixy="0" ixz="0" iyz="0"/>
        </inertial>
    </joint>
    <link name="right_wheel">
        <visual>
            <geometry>
                <cylinder length="0.05" radius="0.05"/>
            </geometry>
            <material name="black"/>
        </visual>
        <collision>
            <geometry>
                <cylinder length="0.05" radius="0.05"/>
            </geometry>
        </collision>
    </link>
    <joint name="right_wheel_to_base" type="continuous">
        <axis xyz="0 0 1"/>
        <parent link="base_link"/>
        <child link="right_wheel"/>
        <origin rpy="0 -1.5708 0" xyz="0.275 0 0"/>
        <inertial>
            <mass value="0.1"/>
            <inertia ixx="5.1458e-5" iyy="5.1458e-5" izz="5.1458e-5" ixy="0" ixz="0" iyz="0"/>
        </inertial>
    </joint>
    <link name="box">
        <visual>
            <geometry>
                <box size="0.2 0.2 0.2"/>
            </geometry>
            <material name="orange"/>
        </visual>
        <collision>
            <geometry>
                <box size="0.2 0.2 0.2"/>
            </geometry>
        </collision>
    </link>
    <joint name="box_to_base" type="fixed">
        <parent link="base_link"/>
        <child link="box"/>
        <origin xyz="0 0 0.1"/>
        <inertial>
            <mass value="1.0"/>
            <inertia ixx="0.015" iyy="0.0375" izz="0.0375" ixy="0" ixz="0" iyz="0"/>
        </inertial>
    </joint>
</robot>
